Workbook

Sheet 1
B3: Total | I3: Total
B5: estructura | C5: 1 2023 | D5: 2 2023 | E5: 3 2023 | F5: 4 2023 | G5: 2023 | J5: 1 2023 | K5: 2 2023 | L5: 3 2023 | M5: 4 2023 | N5: 2023 | P5: 1 2024 | Q5: 2 2024 | R5: 3 2024 | S5: 4 2024
B7: Sector Formal | C7: =+J7/J$19 -> 0.62388653 | D7: =+K7/K$19 -> 0.61574312 | E7: =+L7/L$19 -> 0.62542018 | F7: =+M7/M$19 -> 0.62145855 | G7: =+N7/N$19 -> 0.62166229 | I7: Sector Formal | J7: =SUM(J8:J11) -> 7184021 | K7: =SUM(K8:K11) -> 6992026 | L7: =SUM(L8:L11) -> 7329027 | M7: =SUM(M8:M11) -> 7425692 | N7: =SUM(J7:M7) -> 28930766 | P7: =SUM(P8:P11) -> 7184021 | Q7: =SUM(Q8:Q11) -> 7412348 | R7: =SUM(R8:R11) -> 7273340 | S7: =SUM(S8:S11) -> 7421696
B8: Autónomos profesionales | C8: =+J8/J$19 -> 0.048762964 | D8: =+K8/K$19 -> 0.049184324 | E8: =+L8/L$19 -> 0.048690945 | F8: =+M8/M$19 -> 0.053110296 | G8: =+N8/N$19 -> 0.049963843 | I8: Autónomos profesionales | J8: 561503 | K8: 558509 | L8: 570588 | M8: 634605 | N8: =SUM(J8:M8) -> 2325205 | P8: 561503 | Q8: 675046 | R8: 621380 | S8: 681956 | W8: 4.54 | X8: 4.54
B9: Asalariados Privados | C9: =+J9/J$19 -> 0.36209013 | D9: =+K9/K$19 -> 0.35186462 | E9: =+L9/L$19 -> 0.35172958 | F9: =+M9/M$19 -> 0.35308478 | G9: =+N9/N$19 -> 0.35467402 | I9: Asalariados Privados | J9: 4169449 | K9: 3995573 | L9: 4121766 | M9: 4218944 | N9: =SUM(J9:M9) -> 16505732 | P9: 4169449 | Q9: 4368945 | R9: 4223089 | S9: 4372604 | W9: 33.68 | X9: 38.22
B10: Asalariados Públicos | C10: =+J10/J$19 -> 0.20313448 | D10: =+K10/K$19 -> 0.20545392 | E10: =+L10/L$19 -> 0.21484431 | F10: =+M10/M$19 -> 0.20586748 | G10: =+N10/N$19 -> 0.20735077 | I10: Asalariados Públicos | J10: 2339083 | K10: 2333017 | L10: 2517667 | M10: 2459872 | N10: =SUM(J10:M10) -> 9649639 | P10: 2339083 | Q10: 2271100 | R10: 2336893 | S10: 2240731 | W10: 18.9 | X10: 57.12
B11: Patrones | C11: =+J11/J$19 -> 0.0098989592 | D11: =+K11/K$19 -> 0.0092402514 | E11: =+L11/L$19 -> 0.010155339 | F11: =+M11/M$19 -> 0.0093959961 | G11: =+N11/N$19 -> 0.0096736514 | I11: Patrones | J11: 113986 | K11: 104927 | L11: 119006 | M11: 112271 | N11: =SUM(J11:M11) -> 450190 | P11: 113986 | Q11: 97257 | R11: 91978 | S11: 126405 | W11: 0.92 | X11: 58.04
B12: Sector Informal | C12: =+J12/J$19 -> 0.37611347 | D12: =+K12/K$19 -> 0.38425688 | E12: =+L12/L$19 -> 0.37457982 | F12: =+M12/M$19 -> 0.37854145 | G12: =+N12/N$19 -> 0.37833771 | I12: Sector Informal | J12: =SUM(J13:J16) -> 4330927 | K12: =SUM(K13:K16) -> 4363401 | L12: =SUM(L13:L16) -> 4389538 | M12: =SUM(M13:M16) -> 4523121 | N12: =SUM(J12:M12) -> 17606987 | P12: =SUM(P13:P16) -> 4330927 | Q12: =SUM(Q13:Q16) -> 4356821 | R12: =SUM(R13:R16) -> 4720358 | S12: =SUM(S13:S16) -> 4678926 | W12: 2.61 | X12: 60.65
B13: Patrones (Micro) | C13: =+J13/J$19 -> 0.028033561 | D13: =+K13/K$19 -> 0.026899297 | E13: =+L13/L$19 -> 0.025107767 | F13: =+M13/M$19 -> 0.028180958 | G13: =+N13/N$19 -> 0.027057903 | I13: Patrones (Micro) | J13: 322805 | K13: 305453 | L13: 294227 | M13: 336729 | N13: =SUM(J13:M13) -> 1259214 | P13: 322805 | Q13: 283109 | R13: 339537 | S13: 350323 | W13: 13.12 | X13: 73.77
B14: Asalariados Privados (Micro) | C14: =+J14/J$19 -> 0.14108661 | D14: =+K14/K$19 -> 0.14520793 | E14: =+L14/L$19 -> 0.14726718 | F14: =+M14/M$19 -> 0.14464818 | G14: =+N14/N$19 -> 0.144563 | I14: Asalariados Privados (Micro) | J14: 1624605 | K14: 1648898 | L14: 1725760 | M14: 1728374 | N14: =SUM(J14:M14) -> 6727637 | P14: 1624605 | Q14: 1652625 | R14: 1841441 | S14: 1729585 | W14: 18.89 | X14: 92.66
B15: Autónomos no profesionales | C15: =+J15/J$19 -> 0.20304851 | D15: =+K15/K$19 -> 0.20838019 | E15: =+L15/L$19 -> 0.19776261 | F15: =+M15/M$19 -> 0.20212895 | G15: =+N15/N$19 -> 0.20278233 | I15: Autónomos no profesionales | J15: 2338093 | K15: 2366246 | L15: 2317494 | M15: 2415201 | N15: =SUM(J15:M15) -> 9437034 | P15: 2338093 | Q15: 2386167 | R15: 2492717 | S15: 2553199 | W15: 0.37 | X15: 93.03
B16: Trabajo Familiar | C16: =+J16/J$19 -> 0.0039447855 | D16: =+K16/K$19 -> 0.0037694752 | E16: =+L16/L$19 -> 0.0044422675 | F16: =+M16/M$19 -> 0.0035833685 | G16: =+N16/N$19 -> 0.003934483 | I16: Trabajo Familiar | J16: 45424 | K16: 42804 | L16: 52057 | M16: 42817 | N16: =SUM(J16:M16) -> 183102 | P16: 45424 | Q16: 34920 | R16: 46663 | S16: 45819 | W16: 6.97 | X16: 100
B17: Empleo doméstico | C17: =+J17/J$19 -> 0.074959956 | D17: =+K17/K$19 -> 0.072075933 | E17: =+L17/L$19 -> 0.068599782 | F17: =+M17/M$19 -> 0.070493697 | G17: =+N17/N$19 -> 0.071507965 | I17: Empleo doméstico | J17: 863160 | K17: 818453 | L17: 803891 | M17: 842316 | N17: =SUM(J17:M17) -> 3327820 | P17: 863160 | Q17: 852634 | R17: 790880 | S17: 837467
B19: Ocupados | C19: =+C7+C12 -> 1 | D19: =+D7+D12 -> 1 | E19: =+E7+E12 -> 1 | F19: =+F7+F12 -> 1 | G19: =+G7+G12 -> 1 | I19: Ocupados | J19: =+J7+J12 -> 11514948 | K19: =+K7+K12 -> 11355427 | L19: =+L7+L12 -> 11718565 | M19: =+M7+M12 -> 11948813 | N19: =SUM(J19:M19) -> 46537753 | P19: =+P7+P12 -> 11514948 | Q19: =+Q7+Q12 -> 11769169 | R19: =+R7+R12 -> 11993698 | S19: =+S7+S12 -> 12100622
B22: Total urbano | I22: Total urbano
B24: Sector Formal | I24: Sector Formal
B25: Autónomos profesionales | I25: Autónomos profesionales
B26: Asalariados Privados | I26: Asalariados Privados
B27: Asalariados Públicos | I27: Asalariados Públicos
B28: Patrones | I28: Patrones
B29: Sector Informal | I29: Sector Informal
B30: Patrones (Micro) | I30: Patrones (Micro)
B31: Asalariados Privados (Micro) | I31: Asalariados Privados (Micro)
B32: Autónomos no profesionales | I32: Autónomos no profesionales
B33: Trabajo Familiar | I33: Trabajo Familiar
B34: Empleo doméstico | I34: Empleo doméstico
... B41: Total rural | I41: Total rural

Sheet 2
B3: Jovénes (hasta 24 años) | C3: 1 2023 | D3: 2 2023 | E3: 3 2023 | F3: 4 2023 | G3: 2023 | I3: Jovénes (hasta 24 años) | J3: 1 2023 | K3: 2 2023 | L3: 3 2023 | M3: 4 2023 | N3: 2023
B4: Sector Formal | C4: =+J4/'1'!J7 -> 0.094316679 | D4: =+K4/'1'!K7 -> 0.084830205 | E4: =+L4/'1'!L7 -> 0.080193046 | F4: =+M4/'1'!M7 -> 0.082177257 | G4: =+N4/'1'!N7 -> 0.085330198 | I4: Sector Formal | J4: =SUM(J5:J8) -> 677573 | K4: =SUM(K5:K8) -> 593135 | L4: =SUM(L5:L8) -> 587737 | M4: =SUM(M5:M8) -> 610223 | N4: =SUM(J4:M4) -> 2468668
B5: Autónomos profesionales | C5: =+J5/'1'!J8 -> 0.011291124 | D5: =+K5/'1'!K8 -> 0.0095235708 | E5: =+L5/'1'!L8 -> 0.018563307 | F5: =+M5/'1'!M8 -> 0.008561231 | G5: =+N5/'1'!N8 -> 0.011906047 | I5: Autónomos profesionales | J5: 6340 | K5: 5319 | L5: 10592 | M5: 5433 | N5: =SUM(J5:M5) -> 27684
B6: Asalariados Privados | C6: =+J6/'1'!J9 -> 0.12626009 | D6: =+K6/'1'!K9 -> 0.10858943 | E6: =+L6/'1'!L9 -> 0.11076272 | F6: =+M6/'1'!M9 -> 0.11906415 | G6: =+N6/'1'!N9 -> 0.11627324 | I6: Asalariados Privados | J6: 526435 | K6: 433877 | L6: 456538 | M6: 502325 | N6: =SUM(J6:M6) -> 1919175
B7: Asalariados Públicos | C7: =+J7/'1'!J10 -> 0.061797722 | D7: =+K7/'1'!K10 -> 0.065931796 | E7: =+L7/'1'!L10 -> 0.047125374 | F7: =+M7/'1'!M10 -> 0.041380202 | G7: =+N7/'1'!N10 -> 0.053764291 | I7: Asalariados Públicos | J7: 144550 | K7: 153820 | L7: 118646 | M7: 101790 | N7: =SUM(J7:M7) -> 518806
B8: Patrones | C8: =+J8/'1'!J11 -> 0.0021757058 | D8: =+K8/'1'!K11 -> 0.0011341218 | E8: =+L8/'1'!L11 -> 0.016478161 | F8: =+M8/'1'!M11 -> 0.0060122382 | G8: =+N8/'1'!N11 -> 0.0066705169 | I8: Patrones | J8: 248 | K8: 119 | L8: 1961 | M8: 675 | N8: =SUM(J8:M8) -> 3003
B9: Sector Informal | C9: =+J9/'1'!J12 -> 0.13452363 | D9: =+K9/'1'!K12 -> 0.13101271 | E9: =+L9/'1'!L12 -> 0.14531871 | F9: =+M9/'1'!M12 -> 0.14420441 | G9: =+N9/'1'!N12 -> 0.13883176 | I9: Sector Informal | J9: =SUM(J10:J13) -> 582612 | K9: =SUM(K10:K13) -> 571661 | L9: =SUM(L10:L13) -> 637882 | M9: =SUM(M10:M13) -> 652254 | N9: =SUM(J9:M9) -> 2444409
B10: Patrones (Micro) | C10: =+J10/'1'!J13 -> 0.036170443 | D10: =+K10/'1'!K13 -> 0.020392663 | E10: =+L10/'1'!L13 -> 0.019437373 | F10: =+M10/'1'!M13 -> 0.025109212 | G10: =+N10/'1'!N13 -> 0.025475416 | I10: Patrones (Micro) | J10: 11676 | K10: 6229 | L10: 5719 | M10: 8455 | N10: =SUM(J10:M10) -> 32079
B11: Asalariados Privados (Micro) | C11: =+J11/'1'!J14 -> 0.22637749 | D11: =+K11/'1'!K14 -> 0.21649368 | E11: =+L11/'1'!L14 -> 0.24240277 | F11: =+M11/'1'!M14 -> 0.24137195 | G11: =+N11/'1'!N14 -> 0.23191798 | I11: Asalariados Privados (Micro) | J11: 367774 | K11: 356976 | L11: 418329 | M11: 417181 | N11: =SUM(J11:M11) -> 1560260
B12: Autónomos no profesionales | C12: =+J12/'1'!J15 -> 0.077203088 | D12: =+K12/'1'!K15 -> 0.082216304 | E12: =+L12/'1'!L15 -> 0.0828192 | F12: =+M12/'1'!M15 -> 0.087620037 | G12: =+N12/'1'!N15 -> 0.082505266 | I12: Autónomos no profesionales | J12: 180508 | K12: 194544 | L12: 191933 | M12: 211620 | N12: =SUM(J12:M12) -> 778605
B13: Trabajo Familiar | C13: =+J13/'1'!J16 -> 0.49872314 | D13: =+K13/'1'!K16 -> 0.32501635 | E13: =+L13/'1'!L16 -> 0.42071191 | F13: =+M13/'1'!M16 -> 0.35028143 | G13: =+N13/'1'!N16 -> 0.40122445 | I13: Trabajo Familiar | J13: 22654 | K13: 13912 | L13: 21901 | M13: 14998 | N13: =SUM(J13:M13) -> 73465
B14: Empleo doméstico | C14: =+J14/'1'!J17 -> 0.095707632 | D14: =+K14/'1'!K17 -> 0.11042662 | E14: =+L14/'1'!L17 -> 0.09533382 | F14: =+M14/'1'!M17 -> 0.094120259 | G14: =+N14/'1'!N17 -> 0.098835574 | I14: Empleo doméstico | J14: 82611 | K14: 90379 | L14: 76638 | M14: 79279 | N14: =SUM(J14:M14) -> 328907
B16: Ocupados | C16: =+J16/'1'!J19 -> 0.10943905 | D16: =+K16/'1'!K19 -> 0.10257615 | E16: =+L16/'1'!L19 -> 0.10458781 | F16: =+M16/'1'!M19 -> 0.10565711 | G16: =+N16/'1'!N19 -> 0.10557186 | I16: Ocupados | J16: =+J4+J9 -> 1260185 | K16: =+K4+K9 -> 1164796 | L16: =+L4+L9 -> 1225619 | M16: =+M4+M9 -> 1262477 | N16: =SUM(J16:M16) -> 4913077
B18: Mujeres | C18: 1 2023 | D18: 2 2023 | E18: 3 2023 | F18: 4 2023 | G18: 2023 | I18: Mujeres | J18: 1 2023 | K18: 2 2023 | L18: 3 2023 | M18: 4 2023 | N18: 2023
B19: Sector Formal | C19: =+J19/'1'!J7 -> 0.43305441 | D19: =+K19/'1'!K7 -> 0.4454643 | E19: =+L19/'1'!L7 -> 0.44162056 | F19: =+M19/'1'!M7 -> 0.44380187 | G19: =+N19/'1'!N7 -> 0.44098227 | I19: Sector Formal | J19: =SUM(J20:J23) -> 3111072 | K19: =SUM(K20:K23) -> 3114698 | L19: =SUM(L20:L23) -> 3236649 | M19: =SUM(M20:M23) -> 3295536 | N19: =SUM(J19:M19) -> 12757955
B20: Autónomos profesionales | C20: =+J20/'1'!J8 -> 0.55492847 | D20: =+K20/'1'!K8 -> 0.54424906 | E20: =+L20/'1'!L8 -> 0.53237362 | F20: =+M20/'1'!M8 -> 0.52704123 | G20: =+N20/'1'!N8 -> 0.5392174 | I20: Autónomos profesionales | J20: 311594 | K20: 303968 | L20: 303766 | M20: 334463 | N20: =SUM(J20:M20) -> 1253791
B21: Asalariados Privados | C21: =+J21/'1'!J9 -> 0.3597437 | D21: =+K21/'1'!K9 -> 0.37347609 | E21: =+L21/'1'!L9 -> 0.36380668 | F21: =+M21/'1'!M9 -> 0.36798995 | G21: =+N21/'1'!N9 -> 0.3661903 | I21: Asalariados Privados | J21: 1499933 | K21: 1492251 | L21: 1499526 | M21: 1552529 | N21: =SUM(J21:M21) -> 6044239
B22: Asalariados Públicos | C22: =+J22/'1'!J10 -> 0.54042417 | D22: =+K22/'1'!K10 -> 0.54880612 | E22: =+L22/'1'!L10 -> 0.55844717 | F22: =+M22/'1'!M10 -> 0.56146092 | G22: =+N22/'1'!N10 -> 0.5525157 | I22: Asalariados Públicos | J22: 1264097 | K22: 1280374 | L22: 1405984 | M22: 1381122 | N22: =SUM(J22:M22) -> 5331577
B23: Patrones | C23: =+J23/'1'!J11 -> 0.31098556 | D23: =+K23/'1'!K11 -> 0.36315724 | E23: =+L23/'1'!L11 -> 0.23001361 | F23: =+M23/'1'!M11 -> 0.24424829 | G23: =+N23/'1'!N11 -> 0.2850974 | I23: Patrones | J23: 35448 | K23: 38105 | L23: 27373 | M23: 27422 | N23: =SUM(J23:M23) -> 128348
B24: Sector Informal | C24: =+J24/'1'!J12 -> 0.5563638 | D24: =+K24/'1'!K12 -> 0.54280365 | E24: =+L24/'1'!L12 -> 0.54283435 | F24: =+M24/'1'!M12 -> 0.54589541 | G24: =+N24/'1'!N12 -> 0.54694105 | I24: Sector Informal | J24: =SUM(J25:J29) -> 2409571 | K24: =SUM(K25:K29) -> 2368470 | L24: =SUM(L25:L29) -> 2382792 | M24: =SUM(M25:M29) -> 2469151 | N24: =SUM(J24:M24) -> 9629984
B25: Patrones (Micro) | C25: =+J25/'1'!J13 -> 0.27979121 | D25: =+K25/'1'!K13 -> 0.30145391 | E25: =+L25/'1'!L13 -> 0.37691646 | F25: =+M25/'1'!M13 -> 0.30642148 | G25: =+N25/'1'!N13 -> 0.31486149 | I25: Patrones (Micro) | J25: 90318 | K25: 92080 | L25: 110899 | M25: 103181 | N25: =SUM(J25:M25) -> 396478
B26: Asalariados Privados (Micro) | C26: =+J26/'1'!J14 -> 0.35690275 | D26: =+K26/'1'!K14 -> 0.34431117 | E26: =+L26/'1'!L14 -> 0.34675563 | F26: =+M26/'1'!M14 -> 0.35788493 | G26: =+N26/'1'!N14 -> 0.35146605 | I26: Asalariados Privados (Micro) | J26: 579826 | K26: 567734 | L26: 598417 | M26: 618559 | N26: =SUM(J26:M26) -> 2364536
B27: Autónomos no profesionales | C27: =+J27/'1'!J15 -> 0.36861707 | D27: =+K27/'1'!K15 -> 0.37113681 | E27: =+L27/'1'!L15 -> 0.37372524 | F27: =+M27/'1'!M15 -> 0.36853165 | G27: =+N27/'1'!N15 -> 0.37048145 | I27: Autónomos no profesionales | J27: 861861 | K27: 878201 | L27: 866106 | M27: 890078 | N27: =SUM(J27:M27) -> 3496246
B28: Trabajo Familiar | C28: =+J28/'1'!J16 -> 0.67942057 | D28: =+K28/'1'!K16 -> 0.61861041 | E28: =+L28/'1'!L16 -> 0.55114586 | F28: =+M28/'1'!M16 -> 0.71431908 | G28: =+N28/'1'!N16 -> 0.63689637 | I28: Trabajo Familiar | J28: 30862 | K28: 26479 | L28: 28691 | M28: 30585 | N28: =SUM(J28:M28) -> 116617
B29: Empleo doméstico | C29: =+J29/'1'!J17 -> 0.98093517 | D29: =+K29/'1'!K17 -> 0.98231175 | E29: =+L29/'1'!L17 -> 0.96863754 | F29: =+M29/'1'!M17 -> 0.98151763 | G29: =+N29/'1'!N17 -> 0.97845046 | I29: Empleo doméstico | J29: 846704 | K29: 803976 | L29: 778679 | M29: 826748 | N29: =SUM(J29:M29) -> 3256107
C31: =+J31/'1'!J19 -> 0.47943273 | D31: =+K31/'1'!K19 -> 0.48286762 | E31: =+L31/'1'!L19 -> 0.4795332 | F31: =+M31/'1'!M19 -> 0.48244851 | G31: =+N31/'1'!N19 -> 0.48107048 | J31: =+J19+J24 -> 5520643 | K31: =+K19+K24 -> 5483168 | L31: =+L19+L24 -> 5619441 | M31: =+M19+M24 -> 5764687 | N31: =SUM(J31:M31) -> 22387939
B33: Migrantes | C33: 1 2023 | D33: 2 2023 | E33: 3 2023 | F33: 4 2023 | G33: 2023 | I33: Migrantes | J33: 1 2023 | K33: 2 2023 | L33: 3 2023 | M33: 4 2023 | N33: 2023
B34: Sector Formal | C34: =+J34/'1'!J7 -> 0.045411894 | D34: =+K34/'1'!K7 -> 0.047636694 | E34: =+L34/'1'!L7 -> 0.04335364 | F34: =+M34/'1'!M7 -> 0.049544877 | G34: =+N34/'1'!N7 -> 0.046488987 | I34: Sector Formal | J34: =SUM(J35:J38) -> 326240 | K34: =SUM(K35:K38) -> 333077 | L34: =SUM(L35:L38) -> 317740 | M34: =SUM(M35:M38) -> 367905 | N34: =SUM(J34:M34) -> 1344962
B35: Autónomos profesionales | C35: =+J35/'1'!J8 -> 0.064199123 | D35: =+K35/'1'!K8 -> 0.083373768 | E35: =+L35/'1'!L8 -> 0.053075073 | F35: =+M35/'1'!M8 -> 0.074443158 | G35: =+N35/'1'!N8 -> 0.068870917 | I35: Autónomos profesionales | J35: 36048 | K35: 46565 | L35: 30284 | M35: 47242 | N35: =SUM(J35:M35) -> 160139
B36: Asalariados Privados | C36: =+J36/'1'!J9 -> 0.056387067 | D36: =+K36/'1'!K9 -> 0.059312644 | E36: =+L36/'1'!L9 -> 0.056939914 | F36: =+M36/'1'!M9 -> 0.063925475 | G36: =+N36/'1'!N9 -> 0.059160175 | I36: Asalariados Privados | J36: 235103 | K36: 236988 | L36: 234693 | M36: 269698 | N36: =SUM(J36:M36) -> 976482
B37: Asalariados Públicos | C37: =+J37/'1'!J10 -> 0.015492396 | D37: =+K37/'1'!K10 -> 0.019507359 | E37: =+L37/'1'!L10 -> 0.014325167 | F37: =+M37/'1'!M10 -> 0.018007441 | G37: =+N37/'1'!N10 -> 0.016799696 | I37: Asalariados Públicos | J37: 36238 | K37: 45511 | L37: 36066 | M37: 44296 | N37: =SUM(J37:M37) -> 162111
B38: Patrones | C38: =+J38/'1'!J11 -> 0.16537996 | D38: =+K38/'1'!K11 -> 0.038245637 | E38: =+L38/'1'!L11 -> 0.14030385 | F38: =+M38/'1'!M11 -> 0.059400914 | G38: =+N38/'1'!N11 -> 0.10268998 | I38: Patrones | J38: 18851 | K38: 4013 | L38: 16697 | M38: 6669 | N38: =SUM(J38:M38) -> 46230
B39: Sector Informal | C39: =+J39/'1'!J12 -> 0.10200357 | D39: =+K39/'1'!K12 -> 0.10812162 | E39: =+L39/'1'!L12 -> 0.098814272 | F39: =+M39/'1'!M12 -> 0.085347706 | G39: =+N39/'1'!N12 -> 0.098445861 | I39: Sector Informal | J39: =SUM(J40:J44) -> 441770 | K39: =SUM(K40:K44) -> 471778 | L39: =SUM(L40:L44) -> 433749 | M39: =SUM(M40:M44) -> 386038 | N39: =SUM(J39:M39) -> 1733335
B40: Patrones (Micro) | C40: =+J40/'1'!J13 -> 0.10715757 | D40: =+K40/'1'!K13 -> 0.12141966 | E40: =+L40/'1'!L13 -> 0.036291707 | F40: =+M40/'1'!M13 -> 0.046550787 | G40: =+N40/'1'!N13 -> 0.077851739 | I40: Patrones (Micro) | J40: 34591 | K40: 37088 | L40: 10678 | M40: 15675 | N40: =SUM(J40:M40) -> 98032
B41: Asalariados Privados (Micro) | C41: =+J41/'1'!J14 -> 0.06704522 | D41: =+K41/'1'!K14 -> 0.072878977 | E41: =+L41/'1'!L14 -> 0.065553148 | F41: =+M41/'1'!M14 -> 0.058936897 | G41: =+N41/'1'!N14 -> 0.066009209 | I41: Asalariados Privados (Micro) | J41: 108922 | K41: 120170 | L41: 113129 | M41: 101865 | N41: =SUM(J41:M41) -> 444086
B42: Autónomos no profesionales | C42: =+J42/'1'!J15 -> 0.073865325 | D42: =+K42/'1'!K15 -> 0.089408286 | E42: =+L42/'1'!L15 -> 0.099013849 | F42: =+M42/'1'!M15 -> 0.079767274 | G42: =+N42/'1'!N15 -> 0.085448882 | I42: Autónomos no profesionales | J42: 172704 | K42: 211562 | L42: 229464 | M42: 192654 | N42: =SUM(J42:M42) -> 806384
B43: Trabajo Familiar | C43: =+J43/'1'!J16 -> 0.10230275 | D43: =+K43/'1'!K16 -> 0.1315064 | E43: =+L43/'1'!L16 -> 0.17609543 | F43: =+M43/'1'!M16 -> 0.068757736 | G43: =+N43/'1'!N16 -> 0.12226519 | I43: Trabajo Familiar | J43: 4647 | K43: 5629 | L43: 9167 | M43: 2944 | N43: =SUM(J43:M43) -> 22387
B44: Empleo doméstico | C44: =+J44/'1'!J17 -> 0.14007368 | D44: =+K44/'1'!K17 -> 0.11891825 | E44: =+L44/'1'!L17 -> 0.0887073 | F44: =+M44/'1'!M17 -> 0.086547092 | G44: =+N44/'1'!N17 -> 0.10891394 | I44: Empleo doméstico | J44: 120906 | K44: 97329 | L44: 71311 | M44: 72900 | N44: =SUM(J44:M44) -> 362446
B46: Ocupados | C46: =+J46/'1'!J19 -> 0.066696784 | D46: =+K46/'1'!K19 -> 0.070878444 | E46: =+L46/'1'!L19 -> 0.064128074 | F46: =+M46/'1'!M19 -> 0.063097732 | G46: =+N46/'1'!N19 -> 0.066146232 | I46: Ocupados | J46: =+J34+J39 -> 768010 | K46: =+K34+K39 -> 804855 | L46: =+L34+L39 -> 751489 | M46: =+M34+M39 -> 753943 | N46: =SUM(J46:M46) -> 3078297

Sheet 3
B2: Asalariados
C4: Total | D4: Sector formal | G4: Sector informal | I4: Contrato temporario | J4: Sector formal | M4: Sector informal | O4: Aportes del empleador | P4: Sector formal | S4: Sector informal
D5: privado | E5: público | F5: total | J5: privado | K5: público | L5: Total secfor temporario | P5: privado | Q5: público | R5: Total
B6: 1 2023 | C6: =+F6+G6 -> 8996297 | D6: 4169449 | E6: 2339083 | F6: =+D6+E6 -> 6508532 | G6: 2487765 | I6: 1 2023 | J6: 394907 | K6: 179894 | L6: =+J6+K6 -> 574801 | M6: 351191 | O6: 1 2023 | P6: 3130143 | Q6: 2025657 | R6: =+P6+Q6 -> 5155800 | S6: 620181
B7: 2 2023 | C7: =+F7+G7 -> 8795941 | D7: 3995573 | E7: 2333017 | F7: =+D7+E7 -> 6328590 | G7: 2467351 | I7: 2 2023 | J7: 329897 | K7: 219628 | L7: =+J7+K7 -> 549525 | M7: 307749 | O7: 2 2023 | P7: 3001497 | Q7: 2017886 | R7: =+P7+Q7 -> 5019383 | S7: 595004
B8: 3 2023 | C8: =+F8+G8 -> 9169084 | D8: 4121766 | E8: 2517667 | F8: =+D8+E8 -> 6639433 | G8: 2529651 | I8: 3 2023 | J8: 315642 | K8: 226496 | L8: =+J8+K8 -> 542138 | M8: 427300 | O8: 3 2023 | P8: 3129294 | Q8: 2227966 | R8: =+P8+Q8 -> 5357260 | S8: 608994
B9: 4 2023 | C9: 9963644 | D9: 4218944 | E9: 2459872 | F9: =+D9+E9 -> 6678816 | G9: 2570690 | I9: 4 2023 | J9: 306040 | K9: 251695 | L9: =+J9+K9 -> 557735 | M9: 371582 | O9: 4 2023 | P9: 3189755 | Q9: 2147555 | R9: =+P9+Q9 -> 5337310 | S9: 673333
B10: 2023 | C10: =SUM(C6:C9) -> 36924966 | D10: =SUM(D6:D9) -> 16505732 | E10: =SUM(E6:E9) -> 9649639 | F10: =SUM(F6:F9) -> 26155371 | G10: =SUM(G6:G9) -> 10055457 | I10: 2023 | J10: =SUM(J6:J9) -> 1346486 | K10: =SUM(K6:K9) -> 877713 | L10: =SUM(L6:L9) -> 2224199 | M10: =SUM(M6:M9) -> 1457822 | O10: 2023 | P10: =SUM(P6:P9) -> 12450689 | Q10: =SUM(Q6:Q9) -> 8419064 | R10: =SUM(R6:R9) -> 20869753 | S10: =SUM(S6:S9) -> 2497512
C12: Total | D12: Sector formal | G12: Sector informal | I12: Contrato temporario | J12: Sector formal | M12: Sector informal | O12: Aportes del empleador | P12: Sector formal | S12: Sector informal
D13: privado | E13: público | F13: total | J13: privado | K13: público | L13: Total secfor temporario | P13: privado | Q13: público | R13: Total
B14: 1 2023 | D14: =+D6/$C6 -> 0.4634628 | E14: =+E6/$C6 -> 0.26000509 | F14: =+F6/$C6 -> 0.72346789 | G14: =+G6/$C6 -> 0.27653211 | I14: 1 2023 | J14: =+J6/D6 -> 0.094714433 | K14: =+K6/E6 -> 0.076907916 | L14: =+L6/F6 -> 0.088314999 | M14: =+M6/G6 -> 0.14116727 | O14: 1 2023 | P14: =+P6/D6 -> 0.75073301 | Q14: =+Q6/E6 -> 0.86600475 | R14: =+R6/F6 -> 0.7921602 | S14: =+S6/G6 -> 0.24929244
B15: 2 2023 | D15: =+D7/$C7 -> 0.45425191 | E15: =+E7/$C7 -> 0.26523791 | F15: =+F7/$C7 -> 0.71948982 | G15: =+G7/$C7 -> 0.28051018 | I15: 2 2023 | J15: =+J7/D7 -> 0.08256563 | K15: =+K7/E7 -> 0.094139048 | L15: =+L7/F7 -> 0.086832138 | M15: =+M7/G7 -> 0.1247285 | O15: 2 2023 | P15: =+P7/D7 -> 0.75120565 | Q15: =+Q7/E7 -> 0.86492554 | R15: =+R7/F7 -> 0.79312817 | S15: =+S7/G7 -> 0.24115093
B16: 3 2023 | D16: =+D8/$C8 -> 0.44952866 | E16: =+E8/$C8 -> 0.27458217 | F16: =+F8/$C8 -> 0.72411083 | G16: =+G8/$C8 -> 0.27588917 | I16: 3 2023 | J16: =+J8/D8 -> 0.076579311 | K16: =+K8/E8 -> 0.089962652 | L16: =+L8/F8 -> 0.081654262 | M16: =+M8/G8 -> 0.16891658 | O16: 3 2023 | P16: =+P8/D8 -> 0.75921195 | Q16: =+Q8/E8 -> 0.88493276 | R16: =+R8/F8 -> 0.80688517 | S16: =+S8/G8 -> 0.2407423
B17: 4 2023 | D17: =+D9/$C9 -> 0.42343384 | E17: =+E9/$C9 -> 0.24688477 | F17: =+F9/$C9 -> 0.67031861 | G17: =+G9/$C9 -> 0.25800701 | I17: 4 2023 | J17: =+J9/D9 -> 0.072539479 | K17: =+K9/E9 -> 0.10232036 | L17: =+L9/F9 -> 0.083508065 | M17: =+M9/G9 -> 0.14454563 | O17: 4 2023 | P17: =+P9/D9 -> 0.75605531 | Q17: =+Q9/E9 -> 0.87303526 | R17: =+R9/F9 -> 0.79914015 | S17: =+S9/G9 -> 0.26192695
B18: 2023 | D18: =+D10/$C10 -> 0.44700737 | E18: =+E10/$C10 -> 0.26133102 | F18: =+F10/$C10 -> 0.70833839 | G18: =+G10/$C10 -> 0.27232136 | I18: 2023 | J18: =+J10/D10 -> 0.081576873 | K18: =+K10/E10 -> 0.090958118 | L18: =+L10/F10 -> 0.085037945 | M18: =+M10/G10 -> 0.14497819 | O18: 2023 | P18: =+P10/D10 -> 0.75432516 | Q18: =+Q10/E10 -> 0.8724745 | R18: =+R10/F10 -> 0.79791462 | S18: =+S10/G10 -> 0.24837379

Sheet 4
B3: subocupados | C3: 1 2023 | D3: 2 2023 | E3: 3 2023 | F3: 4 2023 | G3: 2023 | I3: subocupados | J3: 1 2023 | K3: 2 2023 | L3: 3 2023 | M3: 4 2023 | N3: 2023
B4: Sector Formal | C4: =+J4/'1'!J7 -> 0.27329193 | D4: =+K4/'1'!K7 -> 0.34323728 | E4: =+L4/'1'!L7 -> 0.30287759 | F4: =+M4/'1'!M7 -> 0.33055155 | G4: =+N4/'1'!N7 -> 0.31238824 | I4: Sector Formal | J4: =SUM(J5:J8) -> 1963335 | K4: =SUM(K5:K8) -> 2399924 | L4: =SUM(L5:L8) -> 2219798 | M4: =SUM(M5:M8) -> 2454574 | N4: =SUM(J4:M4) -> 9037631
B5: Autónomos profesionales | C5: =+J5/'1'!J8 -> 0.4453636 | D5: =+K5/'1'!K8 -> 0.44112987 | E5: =+L5/'1'!L8 -> 0.47904267 | F5: =+M5/'1'!M8 -> 0.39224872 | G5: =+N5/'1'!N8 -> 0.43811492 | I5: Autónomos profesionales | J5: 250073 | K5: 246375 | L5: 273336 | M5: 248923 | N5: =SUM(J5:M5) -> 1018707
B6: Asalariados Privados | C6: =+J6/'1'!J9 -> 0.19499723 | D6: =+K6/'1'!K9 -> 0.25495642 | E6: =+L6/'1'!L9 -> 0.20176764 | F6: =+M6/'1'!M9 -> 0.22252322 | G6: =+N6/'1'!N9 -> 0.21823812 | I6: Asalariados Privados | J6: 813031 | K6: 1018697 | L6: 831639 | M6: 938813 | N6: =SUM(J6:M6) -> 3602180
B7: Asalariados Públicos | C7: =+J7/'1'!J10 -> 0.37578572 | D7: =+K7/'1'!K10 -> 0.47797294 | E7: =+L7/'1'!L10 -> 0.43385722 | F7: =+M7/'1'!M10 -> 0.50511978 | G7: =+N7/'1'!N10 -> 0.44861274 | I7: Asalariados Públicos | J7: 878994 | K7: 1115119 | L7: 1092308 | M7: 1242530 | N7: =SUM(J7:M7) -> 4328951
B8: Patrones | C8: =+J8/'1'!J11 -> 0.18631235 | D8: =+K8/'1'!K11 -> 0.18806408 | E8: =+L8/'1'!L11 -> 0.18919214 | F8: =+M8/'1'!M11 -> 0.21651183 | G8: =+N8/'1'!N11 -> 0.19501322 | I8: Patrones | J8: 21237 | K8: 19733 | L8: 22515 | M8: 24308 | N8: =SUM(J8:M8) -> 87793
B9: Sector Informal | C9: =+J9/'1'!J12 -> 0.52163059 | D9: =+K9/'1'!K12 -> 0.55727516 | E9: =+L9/'1'!L12 -> 0.55519305 | F9: =+M9/'1'!M12 -> 0.54074432 | G9: =+N9/'1'!N12 -> 0.54374164 | I9: Sector Informal | J9: =SUM(J10:J14) -> 2259144 | K9: =SUM(K10:K14) -> 2431615 | L9: =SUM(L10:L14) -> 2437041 | M9: =SUM(M10:M14) -> 2445852 | N9: =SUM(J9:M9) -> 9573652
B10: Patrones (Micro) | C10: =+J10/'1'!J13 -> 0.23693871 | D10: =+K10/'1'!K13 -> 0.26409955 | E10: =+L10/'1'!L13 -> 0.26446247 | F10: =+M10/'1'!M13 -> 0.23197289 | G10: =+N10/'1'!N13 -> 0.24863049 | I10: Patrones (Micro) | J10: 76485 | K10: 80670 | L10: 77812 | M10: 78112 | N10: =SUM(J10:M10) -> 313079
B11: Asalariados Privados (Micro) | C11: =+J11/'1'!J14 -> 0.32607003 | D11: =+K11/'1'!K14 -> 0.36301457 | E11: =+L11/'1'!L14 -> 0.37928449 | F11: =+M11/'1'!M14 -> 0.35942568 | G11: =+N11/'1'!N14 -> 0.35734464 | I11: Asalariados Privados (Micro) | J11: 529735 | K11: 598574 | L11: 654554 | M11: 621222 | N11: =SUM(J11:M11) -> 2404085
B12: Autónomos no profesionales | C12: =+J12/'1'!J15 -> 0.41790596 | D12: =+K12/'1'!K15 -> 0.44399991 | E12: =+L12/'1'!L15 -> 0.45750884 | F12: =+M12/'1'!M15 -> 0.44591899 | G12: =+N12/'1'!N15 -> 0.44134354 | I12: Autónomos no profesionales | J12: 977103 | K12: 1050613 | L12: 1060274 | M12: 1076984 | N12: =SUM(J12:M12) -> 4164974
B13: Trabajo Familiar | C13: =+J13/'1'!J16 -> 0.64811553 | D13: =+K13/'1'!K16 -> 0.79485562 | E13: =+L13/'1'!L16 -> 0.7171754 | F13: =+M13/'1'!M16 -> 0.66950043 | G13: =+N13/'1'!N16 -> 0.70705399 | I13: Trabajo Familiar | J13: 29440 | K13: 34023 | L13: 37334 | M13: 28666 | N13: =SUM(J13:M13) -> 129463
B14: Empleo doméstico | C14: =+J14/'1'!J17 -> 0.74885421 | D14: =+K14/'1'!K17 -> 0.81585015 | E14: =+L14/'1'!L17 -> 0.75516084 | F14: =+M14/'1'!M17 -> 0.76084035 | G14: =+N14/'1'!N17 -> 0.7698887 | I14: Empleo doméstico | J14: 646381 | K14: 667735 | L14: 607067 | M14: 640868 | N14: =SUM(J14:M14) -> 2562051
B16: Ocupados | C16: =+J16/'1'!J19 -> 0.36669545 | D16: =+K16/'1'!K19 -> 0.42548281 | E16: =+L16/'1'!L19 -> 0.39738987 | F16: =+M16/'1'!M19 -> 0.41011823 | G16: =+N16/'1'!N19 -> 0.39991795 | I16: Ocupados | J16: =+J4+J9 -> 4222479 | K16: =+K4+K9 -> 4831539 | L16: =+L4+L9 -> 4656839 | M16: =+M4+M9 -> 4900426 | N16: =SUM(J16:M16) -> 18611283
B18: sobreocupados | C18: 1 2023 | D18: 2 2023 | E18: 3 2023 | F18: 4 2023 | G18: 2023 | I18: sobreocupados | J18: 1 2023 | K18: 2 2023 | L18: 3 2023 | M18: 4 2023 | N18: 2023
B19: Sector Formal | C19: =+J19/'1'!J7 -> 0.23152855 | D19: =+K19/'1'!K7 -> 0.2238161 | E19: =+L19/'1'!L7 -> 0.23637462 | F19: =+M19/'1'!M7 -> 0.25418412 | G19: =+N19/'1'!N7 -> 0.23670728 | I19: Sector Formal | J19: =SUM(J20:J23) -> 1663306 | K19: =SUM(K20:K23) -> 1564928 | L19: =SUM(L20:L23) -> 1732396 | M19: =SUM(M20:M23) -> 1887493 | N19: =SUM(J19:M19) -> 6848123
B20: Autónomos profesionales | C20: =+J20/'1'!J8 -> 0.19798648 | D20: =+K20/'1'!K8 -> 0.21502429 | E20: =+L20/'1'!L8 -> 0.2128471 | F20: =+M20/'1'!M8 -> 0.28269238 | G20: =+N20/'1'!N8 -> 0.22884391 | I20: Autónomos profesionales | J20: 111170 | K20: 120093 | L20: 121448 | M20: 179398 | N20: =SUM(J20:M20) -> 532109
B21: Asalariados Privados | C21: =+J21/'1'!J9 -> 0.29257535 | D21: =+K21/'1'!K9 -> 0.27183786 | E21: =+L21/'1'!L9 -> 0.29682034 | F21: =+M21/'1'!M9 -> 0.31160997 | G21: =+N21/'1'!N9 -> 0.29348077 | I21: Asalariados Privados | J21: 1219878 | K21: 1086148 | L21: 1223424 | M21: 1314665 | N21: =SUM(J21:M21) -> 4844115
B22: Asalariados Públicos | C22: =+J22/'1'!J10 -> 0.12158996 | D22: =+K22/'1'!K10 -> 0.12883104 | E22: =+L22/'1'!L10 -> 0.13236739 | F22: =+M22/'1'!M10 -> 0.13391713 | G22: =+N22/'1'!N10 -> 0.12929499 | I22: Asalariados Públicos | J22: 284409 | K22: 300565 | L22: 333257 | M22: 329419 | N22: =SUM(J22:M22) -> 1247650
B23: Patrones | C23: =+J23/'1'!J11 -> 0.41977962 | D23: =+K23/'1'!K11 -> 0.55392797 | E23: =+L23/'1'!L11 -> 0.45600222 | F23: =+M23/'1'!M11 -> 0.57014723 | G23: =+N23/'1'!N11 -> 0.49812079 | I23: Patrones | J23: 47849 | K23: 58122 | L23: 54267 | M23: 64011 | N23: =SUM(J23:M23) -> 224249
B24: Sector Informal | C24: =+J24/'1'!J12 -> 0.31580953 | D24: =+K24/'1'!K12 -> 0.32053116 | E24: =+L24/'1'!L12 -> 0.32251503 | F24: =+M24/'1'!M12 -> 0.32900358 | G24: =+N24/'1'!N12 -> 0.32204085 | I24: Sector Informal | J24: =SUM(J25:J29) -> 1367748 | K24: =SUM(K25:K29) -> 1398606 | L24: =SUM(L25:L29) -> 1415692 | M24: =SUM(M25:M29) -> 1488123 | N24: =SUM(J24:M24) -> 5670169
B25: Patrones (Micro) | C25: =+J25/'1'!J13 -> 0.38731123 | D25: =+K25/'1'!K13 -> 0.43847335 | E25: =+L25/'1'!L13 -> 0.43003191 | F25: =+M25/'1'!M13 -> 0.39680871 | G25: =+N25/'1'!N13 -> 0.41224367 | I25: Patrones (Micro) | J25: 125026 | K25: 133933 | L25: 126527 | M25: 133617 | N25: =SUM(J25:M25) -> 519103
B26: Asalariados Privados (Micro) | C26: =+J26/'1'!J14 -> 0.2885366 | D26: =+K26/'1'!K14 -> 0.28545671 | E26: =+L26/'1'!L14 -> 0.29875939 | F26: =+M26/'1'!M14 -> 0.28867305 | G26: =+N26/'1'!N14 -> 0.29043912 | I26: Asalariados Privados (Micro) | J26: 468758 | K26: 470689 | L26: 515587 | M26: 498935 | N26: =SUM(J26:M26) -> 1953969
B27: Autónomos no profesionales | C27: =+J27/'1'!J15 -> 0.30269797 | D27: =+K27/'1'!K15 -> 0.31094147 | E27: =+L27/'1'!L15 -> 0.30354814 | F27: =+M27/'1'!M15 -> 0.31659104 | G27: =+N27/'1'!N15 -> 0.30852935 | I27: Autónomos no profesionales | J27: 707736 | K27: 735764 | L27: 703471 | M27: 764631 | N27: =SUM(J27:M27) -> 2911602
B28: Trabajo Familiar | C28: =+J28/'1'!J16 -> 0.19679024 | D28: =+K28/'1'!K16 -> 0.10571442 | E28: =+L28/'1'!L16 -> 0.095721997 | F28: =+M28/'1'!M16 -> 0.17264171 | G28: =+N28/'1'!N16 -> 0.14111807 | I28: Trabajo Familiar | J28: 8939 | K28: 4525 | L28: 4983 | M28: 7392 | N28: =SUM(J28:M28) -> 25839
B29: Empleo doméstico | C29: =+J29/'1'!J17 -> 0.066371241 | D29: =+K29/'1'!K17 -> 0.065605478 | E29: =+L29/'1'!L17 -> 0.081010983 | F29: =+M29/'1'!M17 -> 0.099188428 | G29: =+N29/'1'!N17 -> 0.078025855 | I29: Empleo doméstico | J29: 57289 | K29: 53695 | L29: 65124 | M29: 83548 | N29: =SUM(J29:M29) -> 259656
B31: Ocupados | C31: =+J31/'1'!J19 -> 0.26322776 | D31: =+K31/'1'!K19 -> 0.26097953 | E31: =+L31/'1'!L19 -> 0.26864108 | F31: =+M31/'1'!M19 -> 0.28250639 | G31: =+N31/'1'!N19 -> 0.26899219 | I31: Ocupados | J31: =+J19+J24 -> 3031054 | K31: =+K19+K24 -> 2963534 | L31: =+L19+L24 -> 3148088 | M31: =+M19+M24 -> 3375616 | N31: =SUM(J31:M31) -> 12518292
B33: más de una ocupación | C33: 1 2023 | D33: 2 2023 | E33: 3 2023 | F33: 4 2023 | G33: 2023 | I33: más de una ocupación | J33: 1 2023 | K33: 2 2023 | L33: 3 2023 | M33: 4 2023 | N33: 2023
B34: Sector Formal | C34: =+J34/'1'!J7 -> 0.085464811 | D34: =+K34/'1'!K7 -> 0.094503653 | E34: =+L34/'1'!L7 -> 0.101326 | F34: =+M34/'1'!M7 -> 0.10431903 | G34: =+N34/'1'!N7 -> 0.096506778 | I34: Sector Formal | J34: =SUM(J35:J38) -> 613981 | K34: =SUM(K35:K38) -> 660772 | L34: =SUM(L35:L38) -> 742621 | M34: =SUM(M35:M38) -> 774641 | N34: =SUM(J34:M34) -> 2792015
B35: Autónomos profesionales | C35: =+J35/'1'!J8 -> 0.10105734 | D35: =+K35/'1'!K8 -> 0.073850198 | E35: =+L35/'1'!L8 -> 0.092511585 | F35: =+M35/'1'!M8 -> 0.10886299 | G35: =+N35/'1'!N8 -> 0.094555534 | I35: Autónomos profesionales | J35: 56744 | K35: 41246 | L35: 52786 | M35: 69085 | N35: =SUM(J35:M35) -> 219861
B36: Asalariados Privados | C36: =+J36/'1'!J9 -> 0.063815866 | D36: =+K36/'1'!K9 -> 0.070306312 | E36: =+L36/'1'!L9 -> 0.079691084 | F36: =+M36/'1'!M9 -> 0.081373917 | G36: =+N36/'1'!N9 -> 0.073839258 | I36: Asalariados Privados | J36: 266077 | K36: 280914 | L36: 328468 | M36: 343312 | N36: =SUM(J36:M36) -> 1218771
B37: Asalariados Públicos | C37: =+J37/'1'!J10 -> 0.12132917 | D37: =+K37/'1'!K10 -> 0.14251246 | E37: =+L37/'1'!L10 -> 0.14039386 | F37: =+M37/'1'!M10 -> 0.1458023 | G37: =+N37/'1'!N10 -> 0.13766349 | I37: Asalariados Públicos | J37: 283799 | K37: 332484 | L37: 353465 | M37: 358655 | N37: =SUM(J37:M37) -> 1328403
B38: Patrones | C38: =+J38/'1'!J11 -> 0.064578106 | D38: =+K38/'1'!K11 -> 0.058402508 | E38: =+L38/'1'!L11 -> 0.066400013 | F38: =+M38/'1'!M11 -> 0.031967293 | G38: =+N38/'1'!N11 -> 0.055487683 | I38: Patrones | J38: 7361 | K38: 6128 | L38: 7902 | M38: 3589 | N38: =SUM(J38:M38) -> 24980
B39: Sector Informal | C39: =+J39/'1'!J12 -> 0.095027 | D39: =+K39/'1'!K12 -> 0.11368838 | E39: =+L39/'1'!L12 -> 0.11438584 | F39: =+M39/'1'!M12 -> 0.11329235 | G39: =+N39/'1'!N12 -> 0.10917024 | I39: Sector Informal | J39: =SUM(J40:J44) -> 411555 | K39: =SUM(K40:K44) -> 496068 | L39: =SUM(L40:L44) -> 502101 | M39: =SUM(M40:M44) -> 512435 | N39: =SUM(J39:M39) -> 1922159
B40: Patrones (Micro) | C40: =+J40/'1'!J13 -> 0.061163861 | D40: =+K40/'1'!K13 -> 0.094410597 | E40: =+L40/'1'!L13 -> 0.058733563 | F40: =+M40/'1'!M13 -> 0.056345013 | G40: =+N40/'1'!N13 -> 0.067372186 | I40: Patrones (Micro) | J40: 19744 | K40: 28838 | L40: 17281 | M40: 18973 | N40: =SUM(J40:M40) -> 84836
B41: Asalariados Privados (Micro) | C41: =+J41/'1'!J14 -> 0.062711244 | D41: =+K41/'1'!K14 -> 0.07241867 | E41: =+L41/'1'!L14 -> 0.096181393 | F41: =+M41/'1'!M14 -> 0.072715165 | G41: =+N41/'1'!N14 -> 0.076246236 | I41: Asalariados Privados (Micro) | J41: 101881 | K41: 119411 | L41: 165986 | M41: 125679 | N41: =SUM(J41:M41) -> 512957
B42: Autónomos no profesionales | C42: =+J42/'1'!J15 -> 0.044378902 | D42: =+K42/'1'!K15 -> 0.06244786 | E42: =+L42/'1'!L15 -> 0.055151815 | F42: =+M42/'1'!M15 -> 0.067702026 | G42: =+N42/'1'!N15 -> 0.057524112 | I42: Autónomos no profesionales | J42: 103762 | K42: 147767 | L42: 127814 | M42: 163514 | N42: =SUM(J42:M42) -> 542857
B43: Trabajo Familiar | C43: =+J43/'1'!J16 -> 0.06511976 | D43: =+K43/'1'!K16 -> 0.0099990655 | E43: =+L43/'1'!L16 -> 0.049503429 | F43: =+M43/'1'!M16 -> 0.050867646 | G43: =+N43/'1'!N16 -> 0.044461557 | I43: Trabajo Familiar | J43: 2958 | K43: 428 | L43: 2577 | M43: 2178 | N43: =SUM(J43:M43) -> 8141
B44: Empleo doméstico | C44: =+J44/'1'!J17 -> 0.21225497 | D44: =+K44/'1'!K17 -> 0.24390405 | E44: =+L44/'1'!L17 -> 0.23441362 | F44: =+M44/'1'!M17 -> 0.23992302 | G44: =+N44/'1'!N17 -> 0.23239478 | I44: Empleo doméstico | J44: 183210 | K44: 199624 | L44: 188443 | M44: 202091 | N44: =SUM(J44:M44) -> 773368
B46: Ocupados | C46: =+J46/'1'!J19 -> 0.089061279 | D46: =+K46/'1'!K19 -> 0.10187552 | E46: =+L46/'1'!L19 -> 0.10621795 | F46: =+M46/'1'!M19 -> 0.1077158 | G46: =+N46/'1'!N19 -> 0.10129784 | I46: Ocupados | J46: =+J34+J39 -> 1025536 | K46: =+K34+K39 -> 1156840 | L46: =+L34+L39 -> 1244722 | M46: =+M34+M39 -> 1287076 | N46: =SUM(J46:M46) -> 4714174
B48: aportes por su cuenta | C48: 1 2023 | D48: 2 2023 | E48: 3 2023 | F48: 4 2023 | G48: 2023 | I48: aportes por su cuenta | J48: 1 2023 | K48: 2 2023 | L48: 3 2023 | M48: 4 2023 | N48: 2023
...

Sheet 5
B1: Índice: Ingreso Asalariados Privados
I2: IPC | J2: 1288.9494 | K2: 1606.8052 | L2: 2055.7637 | M2: 2948.5093
B3: ingreso horario (media) | C3: 1 2023 | D3: 2 2023 | E3: 3 2023 | F3: 4 2023 | G3: promedio índice | I3: ingreso horario (media) | J3: 1 2023 | K3: 2 2023 | L3: 3 2023 | M3: 4 2023
B4: Sector Formal | C4: =+J4/J$6*100 -> 110.20845 | D4: =+K4/K$6*100 -> 110.54514 | E4: =+L4/L$6*100 -> 113.72491 | F4: =+M4/M$6*100 -> 111.82991 | G4: =AVERAGE(C4:F4) -> 111.5771 | I4: Sector Formal | J4: 936.3647 | K4: 1200.801 | L4: 1476.693 | M4: 2062.1
B5: Autónomos profesionales | C5: =+J5/J$6*100 -> 129.31526 | D5: =+K5/K$6*100 -> 118.23892 | E5: =+L5/L$6*100 -> 133.58401 | F5: =+M5/M$6*100 -> 116.71657 | G5: =AVERAGE(C5:F5) -> 124.46369 | I5: Autónomos profesionales | J5: 1098.702 | K5: 1284.375 | L5: 1734.559 | M5: 2152.208
B6: Asalariados Privados | C6: =+J6/J$6*100 -> 100 | D6: =+K6/K$6*100 -> 100 | E6: =+L6/L$6*100 -> 100 | F6: =+M6/M$6*100 -> 100 | G6: =AVERAGE(C6:F6) -> 100 | I6: Asalariados Privados | J6: 849.6306 | K6: 1086.254 | L6: 1298.478 | M6: 1843.961
B7: Asalariados Públicos | C7: =+J7/J$6*100 -> 120.67668 | D7: =+K7/K$6*100 -> 121.22294 | E7: =+L7/L$6*100 -> 131.22895 | F7: =+M7/M$6*100 -> 125.87907 | G7: =AVERAGE(C7:F7) -> 124.75191 | I7: Asalariados Públicos | J7: 1025.306 | K7: 1316.789 | L7: 1703.979 | M7: 2321.161
B8: Patrones | C8: =+J8/J$6*100 -> 206.74926 | D8: =+K8/K$6*100 -> 232.24697 | E8: =+L8/L$6*100 -> 156.36507 | F8: =+M8/M$6*100 -> 224.42183 | G8: =AVERAGE(C8:F8) -> 204.94578 | I8: Patrones | J8: 1756.605 | K8: 2522.792 | L8: 2030.366 | M8: 4138.251
B9: Sector Informal | C9: =+J9/J$6*100 -> 68.989653 | D9: =+K9/K$6*100 -> 64.581755 | E9: =+L9/L$6*100 -> 68.582725 | F9: =+M9/M$6*100 -> 66.389582 | G9: =AVERAGE(C9:F9) -> 67.135929 | I9: Sector Informal | J9: 586.1572 | K9: 701.5219 | L9: 890.5316 | M9: 1224.198
B10: Patrones (Micro) | C10: =+J10/J$6*100 -> 145.54867 | D10: =+K10/K$6*100 -> 110.74049 | E10: =+L10/L$6*100 -> 127.21063 | F10: =+M10/M$6*100 -> 113.11346 | G10: =AVERAGE(C10:F10) -> 124.15331 | I10: Patrones (Micro) | J10: 1236.626 | K10: 1202.923 | L10: 1651.802 | M10: 2085.768
B11: Asalariados Privados (Micro) | C11: =+J11/J$6*100 -> 61.25794 | D11: =+K11/K$6*100 -> 59.815899 | E11: =+L11/L$6*100 -> 65.787792 | F11: =+M11/M$6*100 -> 63.629762 | G11: =AVERAGE(C11:F11) -> 62.622848 | I11: Asalariados Privados (Micro) | J11: 520.4662 | K11: 649.7526 | L11: 854.24 | M11: 1173.308
B12: Autónomos no profesionales | C12: =+J12/J$6*100 -> 67.364911 | D12: =+K12/K$6*100 -> 63.849551 | E12: =+L12/L$6*100 -> 65.591808 | F12: =+M12/M$6*100 -> 65.807086 | G12: =AVERAGE(C12:F12) -> 65.653339 | I12: Autónomos no profesionales | J12: 572.3529 | K12: 693.5683 | L12: 851.6952 | M12: 1213.457
B13: Trabajo Familiar | I13: Trabajo Familiar
B14: Empleo doméstico | C14: =+J14/J$6*100 -> 59.256117 | D14: =+K14/K$6*100 -> 60.26758 | E14: =+L14/L$6*100 -> 60.412183 | F14: =+M14/M$6*100 -> 55.779867 | G14: =AVERAGE(C14:F14) -> 58.928937 | I14: Empleo doméstico | J14: 503.4581 | K14: 654.659 | L14: 784.4389 | M14: 1028.559
B16: Ocupados | C16: =+J16/J$6*100 -> 92.852105 | D16: =+K16/K$6*100 -> 91.23125 | E16: =+L16/L$6*100 -> 95.240043 | F16: =+M16/M$6*100 -> 93.027184 | G16: =AVERAGE(C16:F16) -> 93.087646 | I16: Ocupados | J16: 788.8999 | K16: 991.0031 | L16: 1236.671 | M16: 1715.385
B19: ingreso horario (mediana) | C19: 1 2023 | D19: 2 2023 | E19: 3 2023 | F19: 4 2023 | G19: promedio índice | I19: ingreso horario (mediana) | J19: 1 2023 | K19: 2 2023 | L19: 3 2023 | M19: 4 2023
B20: Sector Formal | C20: =+J20/J$22*100 -> 109.71428 | D20: =+K20/K$22*100 -> 109.375 | E20: =+L20/L$22*100 -> 106.52174 | F20: =+M20/M$22*100 -> 109.37499 | G20: =AVERAGE(C20:F20) -> 108.7465 | I20: Sector Formal | J20: 739.03 | K20: 962.2787 | L20: 1154.734 | M20: 1616.628
B21: Autónomos profesionales | C21: =+J21/J$22*100 -> 114.2857 | D21: =+K21/K$22*100 -> 104.99999 | E21: =+L21/L$22*100 -> 106.52174 | F21: =+M21/M$22*100 -> 104.16668 | G21: =AVERAGE(C21:F21) -> 107.49353 | I21: Autónomos profesionales | J21: 769.8229 | K21: 923.7875 | L21: 1154.734 | M21: 1539.646
B22: Asalariados Privados | C22: =+J22/J$22*100 -> 100 | D22: =+K22/K$22*100 -> 100 | E22: =+L22/L$22*100 -> 100 | F22: =+M22/M$22*100 -> 100 | G22: =AVERAGE(C22:F22) -> 100 | I22: Asalariados Privados | J22: 673.5951 | K22: 879.7977 | L22: 1084.036 | M22: 1478.06
B23: Asalariados Públicos | C23: =+J23/J$22*100 -> 128.57142 | D23: =+K23/K$22*100 -> 131.24995 | E23: =+L23/L$22*100 -> 133.15222 | F23: =+M23/M$22*100 -> 130.20831 | G23: =AVERAGE(C23:F23) -> 130.79548 | I23: Asalariados Públicos | J23: 866.0508 | K23: 1154.734 | L23: 1443.418 | M23: 1924.557
B24: Patrones | C24: =+J24/J$22*100 -> 186.33538 | D24: =+K24/K$22*100 -> 154.41175 | E24: =+L24/L$22*100 -> 142.02905 | F24: =+M24/M$22*100 -> 187.50003 | G24: =AVERAGE(C24:F24) -> 167.56905 | I24: Patrones | J24: 1255.146 | K24: 1358.511 | L24: 1539.646 | M24: 2771.363
B25: Sector Informal | C25: =+J25/J$22*100 -> 65.306116 | D25: =+K25/K$22*100 -> 59.65909 | E25: =+L25/L$22*100 -> 62.137706 | F25: =+M25/M$22*100 -> 62.065972 | G25: =AVERAGE(C25:F25) -> 62.292221 | I25: Sector Informal | J25: 439.8988 | K25: 524.8793 | L25: 673.5951 | M25: 917.3723
B26: Patrones (Micro) | C26: =+J26/J$22*100 -> 95.999986 | D26: =+K26/K$22*100 -> 95.454535 | E26: =+L26/L$22*100 -> 96.83802 | F26: =+M26/M$22*100 -> 101.27316 | G26: =AVERAGE(C26:F26) -> 97.391424 | I26: Patrones (Micro) | J26: 646.6512 | K26: 839.8068 | L26: 1049.759 | M26: 1496.878
B27: Asalariados Privados (Micro) | C27: =+J27/J$22*100 -> 61.714285 | D27: =+K27/K$22*100 -> 59.062498 | E27: =+L27/L$22*100 -> 63.913062 | F27: =+M27/M$22*100 -> 62.5 | G27: =AVERAGE(C27:F27) -> 61.797461 | I27: Asalariados Privados (Micro) | J27: 415.7044 | K27: 519.6305 | L27: 692.8406 | M27: 923.7875
B28: Autónomos no profesionales | C28: =+J28/J$22*100 -> 60.504196 | D28: =+K28/K$22*100 -> 54.687492 | E28: =+L28/L$22*100 -> 53.260888 | F28: =+M28/M$22*100 -> 55.803574 | G28: =AVERAGE(C28:F28) -> 56.064038 | I28: Autónomos no profesionales | J28: 407.5533 | K28: 481.1393 | L28: 577.3672 | M28: 824.8103
B29: Trabajo Familiar | I29: Trabajo Familiar
B30: Empleo doméstico | C30: =+J30/J$22*100 -> 68.571431 | D30: =+K30/K$22*100 -> 65.624995 | E30: =+L30/L$22*100 -> 63.913062 | F30: =+M30/M$22*100 -> 59.570315 | G30: =AVERAGE(C30:F30) -> 64.419951 | I30: Empleo doméstico | J30: 461.8938 | K30: 577.3672 | L30: 692.8406 | M30: 880.485
B32: Ocupados | C32: =+J32/J$22*100 -> 85.714281 | D32: =+K32/K$22*100 -> 87.49999 | E32: =+L32/L$22*100 -> 88.76815 | F32: =+M32/M$22*100 -> 86.805542 | G32: =AVERAGE(C32:F32) -> 87.196991 | I32: Ocupados | J32: 577.3672 | K32: 769.8229 | L32: 962.2787 | M32: 1283.038
B36: p21 (media) | C36: 1 2023 | D36: 2 2023 | E36: 3 2023 | F36: 4 2023 | G36: promedio índice | I36: p21 (media) | J36: 1 2023 | K36: 2 2023 | L36: 3 2023 | M36: 4 2023
B37: Sector Formal | C37: =+J37/J$39*100 -> 100.33974 | D37: =+K37/K$39*100 -> 101.51732 | E37: =+L37/L$39*100 -> 103.7041 | F37: =+M37/M$39*100 -> 101.32532 | G37: =AVERAGE(C37:F37) -> 101.72162 | I37: Sector Formal | J37: 141204.6 | K37: 177206.1 | L37: 225309.4 | M37: 311700.8
B38: Autónomos profesionales | C38: =+J38/J$39*100 -> 87.859572 | D38: =+K38/K$39*100 -> 94.560131 | E38: =+L38/L$39*100 -> 103.18758 | F38: =+M38/M$39*100 -> 90.912927 | G38: =AVERAGE(C38:F38) -> 94.130053 | I38: Autónomos profesionales | J38: 123641.7 | K38: 165061.8 | L38: 224187.2 | M38: 279669.8
B39: Asalariados Privados | C39: =+J39/J$39*100 -> 100 | D39: =+K39/K$39*100 -> 100 | E39: =+L39/L$39*100 -> 100 | F39: =+M39/M$39*100 -> 100 | G39: =AVERAGE(C39:F39) -> 100 | I39: Asalariados Privados | J39: 140726.5 | K39: 174557.5 | L39: 217261.8 | M39: 307623.8
B40: Asalariados Públicos | C40: =+J40/J$39*100 -> 99.51928 | D40: =+K40/K$39*100 -> 100.8321 | E40: =+L40/L$39*100 -> 107.63959 | F40: =+M40/M$39*100 -> 100.36424 | G40: =AVERAGE(C40:F40) -> 102.0888 | I40: Asalariados Públicos | J40: 140050 | K40: 176010 | L40: 233859.7 | M40: 308744.3
B41: Patrones | C41: =+J41/J$39*100 -> 194.80069 | D41: =+K41/K$39*100 -> 202.52117 | E41: =+L41/L$39*100 -> 160.06367 | F41: =+M41/M$39*100 -> 220.13215 | G41: =AVERAGE(C41:F41) -> 194.37942 | I41: Patrones | J41: 274136.2 | K41: 353515.9 | L41: 347757.2 | M41: 677178.9
B42: Sector Informal | C42: =+J42/J$39*100 -> 50.906176 | D42: =+K42/K$39*100 -> 49.697538 | E42: =+L42/L$39*100 -> 51.694085 | F42: =+M42/M$39*100 -> 49.553708 | G42: =AVERAGE(C42:F42) -> 50.462877 | I42: Sector Informal | J42: 71638.48 | K42: 86750.78 | L42: 112311.5 | M42: 152439
B43: Patrones (Micro) | C43: =+J43/J$39*100 -> 103.98098 | D43: =+K43/K$39*100 -> 101.39622 | E43: =+L43/L$39*100 -> 121.02229 | F43: =+M43/M$39*100 -> 102.31705 | G43: =AVERAGE(C43:F43) -> 107.17913 | I43: Patrones (Micro) | J43: 146328.8 | K43: 176994.7 | L43: 262935.2 | M43: 314751.6
B44: Asalariados Privados (Micro) | C44: =+J44/J$39*100 -> 54.234078 | D44: =+K44/K$39*100 -> 53.913581 | E44: =+L44/L$39*100 -> 54.019943 | F44: =+M44/M$39*100 -> 54.126501 | G44: =AVERAGE(C44:F44) -> 54.073526 | I44: Asalariados Privados (Micro) | J44: 76321.72 | K44: 94110.2 | L44: 117364.7 | M44: 166506
B45: Autónomos no profesionales | C45: =+J45/J$39*100 -> 51.393675 | D45: =+K45/K$39*100 -> 49.691958 | E45: =+L45/L$39*100 -> 50.635869 | F45: =+M45/M$39*100 -> 48.806172 | G45: =AVERAGE(C45:F45) -> 50.131918 | I45: Autónomos no profesionales | J45: 72324.52 | K45: 86741.04 | L45: 110012.4 | M45: 150139.4
B46: Trabajo Familiar | I46: Trabajo Familiar | J46: 0 | K46: 0 | L46: 0 | M46: 0
B47: Empleo doméstico | C47: =+J47/J$39*100 -> 25.822088 | D47: =+K47/K$39*100 -> 25.946785 | E47: =+L47/L$39*100 -> 26.84882 | F47: =+M47/M$39*100 -> 24.144273 | G47: =AVERAGE(C47:F47) -> 25.690492 | I47: Empleo doméstico | J47: 36338.52 | K47: 45292.06 | L47: 58332.23 | M47: 74273.53
...
